<mujoco model="bdx">
  <option iterations="50" timestep="0.001" solver="PGS" gravity="0 0 -9.81" />

  <compiler angle="radian" meshdir="meshes" eulerseq="zyx" autolimits="true" />

  <default>
    <joint limited="true" damping="0.01" armature="0.01" frictionloss="0.01" />
    <geom condim="4" contype="1" conaffinity="15" friction="0.9 0.2 0.2" solref="0.001 2" />
    <motor ctrllimited="true" />
    <equality solref="0.001 2" />
    <default class="visualgeom">
      <geom material="visualgeom" condim="1" contype="0" conaffinity="0" />
    </default>
  </default>

  <asset>
    <mesh name="pelvis" file="pelvis.stl" scale="0.001 0.001 0.001" />
    <mesh name="left_foot" file="left_foot.stl" scale="0.001 0.001 0.001" />
    <mesh name="left_shin" file="left_shin.stl" scale="0.001 0.001 0.001" />
    <mesh name="right_foot" file="right_foot.stl" scale="0.001 0.001 0.001" />
    <mesh name="right_shin" file="right_shin.stl" scale="0.001 0.001 0.001" />
    <mesh name="ear_right" file="ear_right.stl" scale="0.001 0.001 0.001" />
    <mesh name="ear_left" file="ear_left.stl" scale="0.001 0.001 0.001" />
    <mesh name="head_body_roll" file="head_body_roll.stl" scale="0.001 0.001 0.001" />
    <texture name="texplane" type="2d" builtin="checker" rgb1=".0 .0 .0" rgb2=".8 .8 .8" width="100" height="100" />
    <material name="matplane" reflectance="0." texture="texplane" texrepeat="1 1" texuniform="true" />
    <material name="visualgeom" rgba="0.5 0.9 0.2 1" />
  </asset>

  <worldbody>
    <light directional="true" diffuse="0.4 0.4 0.4" specular="0.1 0.1 0.1" pos="0 0 5.0" dir="0 0 -1" castshadow="false" />
    <light directional="true" diffuse="0.6 0.6 0.6" specular="0.2 0.2 0.2" pos="0 0 4" dir="0 0 -1" />
    <geom name="ground" type="plane" pos="0 0 0" size="100 100 0.001" quat="1 0 0 0" material="matplane" condim="3" conaffinity="15" />
    <camera name="fixed" pos="0 -3.0 0.5519919449499777" xyaxes="1 0 0 0 0 1" />
    <camera name="track" mode="trackcom" pos="0 -3.0 0.5519919449499777" xyaxes="1 0 0 0 0 1" />
    <body name="root" pos="0 0 0.05199194494997771" quat="1 0 0 0">
      <freejoint name="root" />
      <site name="imu" size="0.01" pos="0 0 0" />
      <geom type="mesh" rgba="0.7 0.7 0.7 1" mesh="pelvis" contype="1" conaffinity="0" density="0" group="1" class="visualgeom" />
      <geom type="mesh" rgba="0.7 0.7 0.7 1" mesh="pelvis" />
      <body name="left_hip_rotation" pos="-0.033111 0.046658 0.363959">
        <inertial pos="-0.00508397 0.00309242 -0.0631043" quat="0.999573 0.0213461 0.0199274 0.00141326" mass="0.633" diaginertia="0.00533636 0.004183 0.00196963" />
        <joint name="left_hip_yaw" pos="0 0 0" axis="0 0 -1" range="-0.785398 0.785398" actuatorfrcrange="-23.7 23.7" />
        <body name="left_hip" pos="-0.0073 0.00275 -0.076">
          <inertial pos="0.0189112 0.0234713 0.000362123" quat="0.704899 0.708795 -0.00571972 -0.0263546" mass="0.633" diaginertia="0.00149816 0.00136791 0.000505934" />
          <joint name="left_hip_roll" pos="0 0 0" axis="1 0 0" range="-0.785398 0.785398" actuatorfrcrange="-23.7 23.7" />
          <body name="left_thigh" pos="0.017466 0.069601 0.000785">
            <inertial pos="-0.0341087 0.0267727 -0.0344467" quat="0.633403 0.297734 0.294346 0.650781" mass="0.633" diaginertia="0.0473468 0.0413446 0.0120747" />
            <joint name="left_hip_pitch" pos="0 0 0" axis="0 1 0" range="-0.785398 0.785398" actuatorfrcrange="-23.7 23.7" />
            <body name="left_shin" pos="-0.079306 0 -0.077708">
              <inertial pos="0.0222946 -0.0149367 -0.0900588" quat="0.708097 -0.166338 -0.130184 0.673783" mass="0.633" diaginertia="0.0117688 0.0102167 0.00215741" />
              <joint name="left_knee" pos="0 0 0" axis="0 -1 0" range="-0.785398 0.785398" actuatorfrcrange="-23.7 23.7" />
              <geom pos="0.102251 -0.119009 -0.211036" quat="1 0 0 0" type="mesh" rgba="0.7 0.7 0.7 1" mesh="left_shin" contype="1" conaffinity="0" density="0" group="1" class="visualgeom" />
              <geom type="mesh" rgba="0.7 0.7 0.7 1" mesh="left_shin" pos="0.102251 -0.119009 -0.211036" quat="1 0 0 0" />
              <body name="left_foot_link" pos="0.045 -0.0152 -0.13">
                <inertial pos="0.0317645 0.00793337 -0.0421515" quat="0.540863 0.468785 0.58167 0.386481" mass="0.678" diaginertia="0.0103795 0.00833717 0.00325637" />
                <joint name="left_ankle" pos="0 0 0" axis="0 1 0" range="-0.785398 0.785398" actuatorfrcrange="-23.7 23.7" />
                <geom pos="0.057251 -0.103809 -0.081036" quat="1 0 0 0" type="mesh" rgba="0.7 0.7 0.7 1" mesh="left_foot" contype="1" conaffinity="0" density="0" group="1" class="visualgeom" />
                <geom type="mesh" rgba="0.7 0.7 0.7 1" mesh="left_foot" pos="0.057251 -0.103809 -0.081036" quat="1 0 0 0" />
              </body>
            </body>
          </body>
        </body>
      </body>
      <body name="right_hip_rotation" pos="-0.033111 -0.046658 0.363959">
        <inertial pos="-0.00508397 -0.00309242 -0.0631043" quat="0.999573 -0.0213461 0.0199274 -0.00141326" mass="0.633" diaginertia="0.00533636 0.004183 0.00196963" />
        <joint name="right_hip_yaw" pos="0 0 0" axis="0 0 -1" range="-0.785398 0.785398" actuatorfrcrange="-23.7 23.7" />
        <body name="right_hip" pos="-0.0073 -0.00275 -0.076">
          <inertial pos="0.0189112 -0.0234713 0.000362123" quat="0.708795 0.704899 0.0263546 0.00571972" mass="0.633" diaginertia="0.00149816 0.00136791 0.000505934" />
          <joint name="right_hip_roll" pos="0 0 0" axis="1 0 0" range="-0.785398 0.785398" actuatorfrcrange="-23.7 23.7" />
          <body name="right_thigh" pos="0.017466 -0.069601 0.000785">
            <inertial pos="-0.0341087 -0.0267727 -0.0344467" quat="0.650781 0.294346 0.297734 0.633403" mass="0.633" diaginertia="0.0473468 0.0413446 0.0120747" />
            <joint name="right_hip_pitch" pos="0 0 0" axis="0 -1 0" range="-0.785398 0.785398" actuatorfrcrange="-23.7 23.7" />
            <body name="right_shin" pos="-0.079306 0 -0.077708">
              <inertial pos="0.0222946 0.0149367 -0.0900588" quat="0.673783 -0.130184 -0.166338 0.708097" mass="0.633" diaginertia="0.0117688 0.0102167 0.00215741" />
              <joint name="right_knee" pos="0 0 0" axis="0 1 0" range="-0.785398 0.785398" actuatorfrcrange="-23.7 23.7" />
              <geom pos="0.102251 0.119009 -0.211036" quat="1 0 0 0" type="mesh" rgba="0.7 0.7 0.7 1" mesh="right_shin" contype="1" conaffinity="0" density="0" group="1" class="visualgeom" />
              <geom type="mesh" rgba="0.7 0.7 0.7 1" mesh="right_shin" pos="0.102251 0.119009 -0.211036" quat="1 0 0 0" />
              <body name="right_foot_link" pos="0.045 0.0152 -0.13">
                <inertial pos="0.0317645 -0.00793337 -0.0421515" quat="0.386481 0.58167 0.468785 0.540863" mass="0.678" diaginertia="0.0103795 0.00833717 0.00325637" />
                <joint name="right_ankle" pos="0 0 0" axis="0 -1 0" range="-0.785398 0.785398" actuatorfrcrange="-23.7 23.7" />
                <geom pos="0.057251 0.103809 -0.081036" quat="1 0 0 0" type="mesh" rgba="0.7 0.7 0.7 1" mesh="right_foot" contype="1" conaffinity="0" density="0" group="1" class="visualgeom" />
                <geom type="mesh" rgba="0.7 0.7 0.7 1" mesh="right_foot" pos="0.057251 0.103809 -0.081036" quat="1 0 0 0" />
              </body>
            </body>
          </body>
        </body>
      </body>
      <body name="neck" pos="0.056339 0.0119 0.395171">
        <inertial pos="-0.0240043 -0.0164112 0.050435" quat="0.415022 -0.234316 -0.0652626 0.876694" mass="0.633" diaginertia="0.00651818 0.00640093 0.00104188" />
        <joint name="neck_pitch" pos="0 0 0" axis="0 -1 0" range="-0.785398 0.785398" actuatorfrcrange="-23.7 23.7" />
        <body name="head_body_pitch" pos="-0.065022 -0.01175 0.11088">
          <inertial pos="-0.0129682 -0.00171465 0.0277559" quat="0.975914 -0.0920927 -0.197246 0.0143444" mass="0.2" diaginertia="0.000404789 0.00034123 0.000159981" />
          <joint name="head_pitch" pos="0 0 0" axis="0 -1 0" range="-0.785398 0.785398" actuatorfrcrange="-7.3 7.3" />
          <body name="head_body_yaw" pos="0.000299 0.0007 0.02897">
            <inertial pos="0.00785461 -1.46108e-06 0.0225451" quat="0.541584 0.454629 0.454629 0.541584" mass="0.2" diaginertia="0.000559 0.000550027 0.000215973" />
            <joint name="head_yaw" pos="0 0 0" axis="0 0 1" range="-0.785398 0.785398" actuatorfrcrange="-7.3 7.3" />
            <body name="head_body_roll" pos="0.039892 0 0.02715">
              <inertial pos="-0.0339687 0.00148766 0.00242765" quat="-0.0651364 0.688995 0.064254 0.718968" mass="0.4" diaginertia="0.0807248 0.047202 0.0412992" />
              <joint name="head_roll" pos="0 0 0" axis="1 0 0" range="-0.785398 0.785398" actuatorfrcrange="-7.3 7.3" />
              <geom pos="-0.031508 -0.00085 -0.562171" quat="1 0 0 0" type="mesh" rgba="0.7 0.7 0.7 1" mesh="head_body_roll" contype="1" conaffinity="0" density="0" group="1" class="visualgeom" />
              <geom type="mesh" rgba="0.7 0.7 0.7 1" mesh="head_body_roll" pos="-0.031508 -0.00085 -0.562171" quat="1 0 0 0" />
              <body name="ear_left" pos="-0.16665 0.0683 0.001231">
                <inertial pos="0.000161565 0.0247291 0.016145" quat="0.998004 -0.0231719 0.0382937 0.0445513" mass="0.0964016" diaginertia="0.000208107 0.000200388 1.95059e-05" />
                <joint name="left_antenna" pos="0 0 0" axis="0 -1 0" range="-0.785398 0.785398" actuatorfrcrange="-0.2943 0.2943" />
                <geom pos="0.135142 -0.06915 -0.563402" quat="1 0 0 0" type="mesh" rgba="0.7 0.7 0.7 1" mesh="ear_left" contype="1" conaffinity="0" density="0" group="1" class="visualgeom" />
                <geom type="mesh" rgba="0.7 0.7 0.7 1" mesh="ear_left" pos="0.135142 -0.06915 -0.563402" quat="1 0 0 0" />
              </body>
              <body name="ear_right" pos="-0.16665 -0.0697 0.001231">
                <inertial pos="0.000161565 -0.0247291 0.016145" quat="0.998004 0.0231719 0.0382937 -0.0445513" mass="0.0964016" diaginertia="0.000208107 0.000200388 1.95059e-05" />
                <joint name="right_antenna" pos="0 0 0" axis="0 -1 0" range="-0.785398 0.785398" actuatorfrcrange="-0.2943 0.2943" />
                <geom pos="0.135142 0.06885 -0.563402" type="mesh" rgba="0.7 0.7 0.7 1" mesh="ear_right" contype="1" conaffinity="0" density="0" group="1" class="visualgeom" />
                <geom type="mesh" rgba="0.7 0.7 0.7 1" mesh="ear_right" pos="0.135142 0.06885 -0.563402" />
              </body>
            </body>
          </body>
        </body>
      </body>
    </body>
  </worldbody>

  <actuator>
    <motor name="left_hip_yaw" joint="left_hip_yaw" ctrllimited="true" ctrlrange="-23.7 23.7" gear="1" />
    <motor name="left_hip_roll" joint="left_hip_roll" ctrllimited="true" ctrlrange="-23.7 23.7" gear="1" />
    <motor name="left_hip_pitch" joint="left_hip_pitch" ctrllimited="true" ctrlrange="-23.7 23.7" gear="1" />
    <motor name="left_knee" joint="left_knee" ctrllimited="true" ctrlrange="-23.7 23.7" gear="1" />
    <motor name="left_ankle" joint="left_ankle" ctrllimited="true" ctrlrange="-23.7 23.7" gear="1" />
    <motor name="right_hip_yaw" joint="right_hip_yaw" ctrllimited="true" ctrlrange="-23.7 23.7" gear="1" />
    <motor name="right_hip_roll" joint="right_hip_roll" ctrllimited="true" ctrlrange="-23.7 23.7" gear="1" />
    <motor name="right_hip_pitch" joint="right_hip_pitch" ctrllimited="true" ctrlrange="-23.7 23.7" gear="1" />
    <motor name="right_knee" joint="right_knee" ctrllimited="true" ctrlrange="-23.7 23.7" gear="1" />
    <motor name="right_ankle" joint="right_ankle" ctrllimited="true" ctrlrange="-23.7 23.7" gear="1" />
    <motor name="neck_pitch" joint="neck_pitch" ctrllimited="true" ctrlrange="-23.7 23.7" gear="1" />
    <motor name="head_pitch" joint="head_pitch" ctrllimited="true" ctrlrange="-7.3 7.3" gear="1" />
    <motor name="head_yaw" joint="head_yaw" ctrllimited="true" ctrlrange="-7.3 7.3" gear="1" />
    <motor name="head_roll" joint="head_roll" ctrllimited="true" ctrlrange="-7.3 7.3" gear="1" />
    <motor name="left_antenna" joint="left_antenna" ctrllimited="true" ctrlrange="-0.2943 0.2943" gear="1" />
    <motor name="right_antenna" joint="right_antenna" ctrllimited="true" ctrlrange="-0.2943 0.2943" gear="1" />
  </actuator>

  <sensor>
    <actuatorpos name="left_hip_yaw_p" actuator="left_hip_yaw" />
    <actuatorvel name="left_hip_yaw_v" actuator="left_hip_yaw" />
    <actuatorfrc name="left_hip_yaw_f" actuator="left_hip_yaw" noise="0.001" />
    <actuatorpos name="left_hip_roll_p" actuator="left_hip_roll" />
    <actuatorvel name="left_hip_roll_v" actuator="left_hip_roll" />
    <actuatorfrc name="left_hip_roll_f" actuator="left_hip_roll" noise="0.001" />
    <actuatorpos name="left_hip_pitch_p" actuator="left_hip_pitch" />
    <actuatorvel name="left_hip_pitch_v" actuator="left_hip_pitch" />
    <actuatorfrc name="left_hip_pitch_f" actuator="left_hip_pitch" noise="0.001" />
    <actuatorpos name="left_knee_p" actuator="left_knee" />
    <actuatorvel name="left_knee_v" actuator="left_knee" />
    <actuatorfrc name="left_knee_f" actuator="left_knee" noise="0.001" />
    <actuatorpos name="left_ankle_p" actuator="left_ankle" />
    <actuatorvel name="left_ankle_v" actuator="left_ankle" />
    <actuatorfrc name="left_ankle_f" actuator="left_ankle" noise="0.001" />
    <actuatorpos name="right_hip_yaw_p" actuator="right_hip_yaw" />
    <actuatorvel name="right_hip_yaw_v" actuator="right_hip_yaw" />
    <actuatorfrc name="right_hip_yaw_f" actuator="right_hip_yaw" noise="0.001" />
    <actuatorpos name="right_hip_roll_p" actuator="right_hip_roll" />
    <actuatorvel name="right_hip_roll_v" actuator="right_hip_roll" />
    <actuatorfrc name="right_hip_roll_f" actuator="right_hip_roll" noise="0.001" />
    <actuatorpos name="right_hip_pitch_p" actuator="right_hip_pitch" />
    <actuatorvel name="right_hip_pitch_v" actuator="right_hip_pitch" />
    <actuatorfrc name="right_hip_pitch_f" actuator="right_hip_pitch" noise="0.001" />
    <actuatorpos name="right_knee_p" actuator="right_knee" />
    <actuatorvel name="right_knee_v" actuator="right_knee" />
    <actuatorfrc name="right_knee_f" actuator="right_knee" noise="0.001" />
    <actuatorpos name="right_ankle_p" actuator="right_ankle" />
    <actuatorvel name="right_ankle_v" actuator="right_ankle" />
    <actuatorfrc name="right_ankle_f" actuator="right_ankle" noise="0.001" />
    <actuatorpos name="neck_pitch_p" actuator="neck_pitch" />
    <actuatorvel name="neck_pitch_v" actuator="neck_pitch" />
    <actuatorfrc name="neck_pitch_f" actuator="neck_pitch" noise="0.001" />
    <actuatorpos name="head_pitch_p" actuator="head_pitch" />
    <actuatorvel name="head_pitch_v" actuator="head_pitch" />
    <actuatorfrc name="head_pitch_f" actuator="head_pitch" noise="0.001" />
    <actuatorpos name="head_yaw_p" actuator="head_yaw" />
    <actuatorvel name="head_yaw_v" actuator="head_yaw" />
    <actuatorfrc name="head_yaw_f" actuator="head_yaw" noise="0.001" />
    <actuatorpos name="head_roll_p" actuator="head_roll" />
    <actuatorvel name="head_roll_v" actuator="head_roll" />
    <actuatorfrc name="head_roll_f" actuator="head_roll" noise="0.001" />
    <actuatorpos name="left_antenna_p" actuator="left_antenna" />
    <actuatorvel name="left_antenna_v" actuator="left_antenna" />
    <actuatorfrc name="left_antenna_f" actuator="left_antenna" noise="0.001" />
    <actuatorpos name="right_antenna_p" actuator="right_antenna" />
    <actuatorvel name="right_antenna_v" actuator="right_antenna" />
    <actuatorfrc name="right_antenna_f" actuator="right_antenna" noise="0.001" />
    <framequat name="orientation" objtype="site" noise="0.001" objname="imu" />
    <gyro name="angular-velocity" site="imu" noise="0.005" cutoff="34.9" />
  </sensor>
</mujoco>